Workbook
Name campo: #REF!
Name campo: #REF!
Name campo: #REF!
Name Campo_Listagem: #REF!
Name Campo_Listagem: #REF!
Name Campo_Listagem: #REF!
Name Conteúdo: #REF!
Name FX_BRLEUR: #REF!
Name hj: #REF!
Name j: #REF!
Name periodo_selecionado: #REF!
Name PeriodoInPlanejado: #REF!=MEDIAN(#REF!,#REF!,#REF!+#REF!-1)
Name PeriodoInReal: #REF!=MEDIAN(#REF!,#REF!,#REF!+#REF!-1)
Name Plano: PeriodoInPlanejado*(#REF!>0)
Name PorcentagemConcluída: PorcentagemConcluídaPosterior*PeriodoInPlanejado
Name PorcentagemConcluídaPosterior: (#REF!=MEDIAN(#REF!,#REF!,#REF!+#REF!)*(#REF!>0))*((#REF!<(INT(#REF!+#REF!*#REF!)))+(#REF!=#REF!))*(#REF!>0)
Name Real: (PeriodoInReal*(#REF!>0))*PeriodoInPlanejado
Name RealPosterior: PeriodoInReal*(#REF!>0)
Name Resuumo: #REF!
Name Status: #REF!

Sheet RESUMO
D1: PLANILHA DE ESTIMATIVA DE CUSTOS
C2: Evento: | D2: PRESS KIT THE BLEND
C3: Data do Evento: | D3: -
C4: Horário do Evento: | D4: -
C5: Data da Montagem: | D5: -
C6: Qtde Pessoas: | D6: -
C7: Local: | D7: -
C8: PIT: | D8: BO_0001_26
C9: Atendimento: | D9: Dida Dourado
C10: Pré Produção: | D10: Keila Parente / Cesar Laranjeira
C11: Produção: | D11: -
B15: RESUMO GERAL | F15: CASHFLOW
B16: PLANILHA | D16: VALOR | F16: À VISTA ANTECIPADO | G16: 75 DIAS
B17: GERAL | D17: =GERAL!I$43 -> 99000 | F17: =GERAL!K$43 -> 0 | G17: =GERAL!L$43 -> 99000
D18: =SUM(D17:D17) -> 99000 | F18: =SUM(F17:F17) -> 0 | G18: =SUM(G17:G17) -> 99000

Sheet GERAL
I2: PLANILHA DE ESTIMATIVA DE CUSTOS
H3: Evento: | I3: =RESUMO!D2 -> PRESS KIT THE BLEND
H4: Data do Evento: | I4: =RESUMO!D3 -> -
H5: Horário do Evento: | I5: =RESUMO!D4 -> -
H6: Data da Montagem: | I6: =RESUMO!D5 -> -
H7: Qtde Pessoas: | I7: =RESUMO!D6 -> -
H8: Local: | I8: =RESUMO!D7 -> -
H9: PIT: | I9: =RESUMO!D8 -> BO_0001_26
H10: Atendimento: | I10: =RESUMO!D9 -> Dida Dourado
H11: Pré Produção: | I11: =RESUMO!D10 -> Keila Parente / Cesar Laranjeira
H12: Produção: | I12: =RESUMO!D11 -> -
I14: =I43 -> 99000
B15: ITEM | C15: DESCRIÇÃO | D15: INTERNO (I) TERCEIRO (T) CRIAÇÃO (C) | E15: QUANT | F15: UNIDADE | G15: VALOR UNIT | H15: VALOR TOTAL | I15: SUBTOTAL | K15: CASHFLOW
B16: 1 | C16: CRIAÇÃO E FINALIZAÇÃO | I16: =SUM(H17:H18) -> 5000 | K16: À VISTA ANTECIPADO | L16: =RESUMO!G$16 -> 75 DIAS
B17: 1.1 | C17: Desenvolvimento do KV e Conceito Criação e finalização. | D17: ( I ) | E17: 1 | F17: 1 | G17: 5000 | H17: =E17*F17*G17 -> 5000 | K17: 0 | L17: =H17 -> 5000
B18: 1.2 | C18: Logo, elementos da marca e banco de imagens Disponibilidade de materiais gerais para realização do trabalho. | D18: ( I ) | E18: 1 | F18: 1 | G18: 0 | H18: RESPONSABILIDADE CLIENTE | K18: 0 | L18: =H18 -> RESPONSABILIDADE CLIENTE
B19: 2 | C19: MATERIAIS | I19: =SUM(H20:H21) -> 70000 | K19: À VISTA ANTECIPADO | L19: =L$16 -> 75 DIAS
B20: 2.1 | C20: Sacola premium para press kit Boticário - THE BLEND Sacola- em cartão rígido- faca especial- revestimento interno e externo em impressão total / acabamento em laminação - fechamento com imã. Acabamento especial - HOT STAMPING - Frases: - THE BLEND - AMBER SAFFRON - aplicado na parte frontal superior - O BOTICÁRIO - aplicado na parte frontal inferior. Logo ícone O Boticário - aplicado nas 2 laterais fixas Bolso Interno - fixado na parte fixa traseira em papel dourado percalux dourado ou similar Carta - inserida no bolso acima- impressão 4 x 4 cor- couche 250 Berço - em cartão rígido- faca especial para encaixar o perfume revestimento em percalux dourado ou similar- logo posicionado na parte frontal do berço - aplicado em serigrafia em 1 cor Prazos: - PRAZO MÁXIMO DE APROVAÇÃO: 06/03/2026 - até as 16:00h - 1ª Entrega: 50 unidades em 16/03 - 2ª e 3ª entregas: 50 unidades em 23/03 e 100 unidades em 30/03/2026 *Prazo de produção de modelo 5 dias uteis *Prazo para produção 20 dias uteis *Valor sujeito a alteração sem aviso prévio. *Valor sujeito a alteração em caso de aprovação após a data sinalizada para aprovação. *Produção a ser avaliada caso a aprovação ocorra após a data sinalizada. *O prazo de produção/serviço inicia quando o fornecedor recebe a aprovação formalizada e confirma a disponibilidade para execução do serviço ou produto/material em estoque. *Caso a aprovação e a liberação da arte seja realizado após o prazo estipulado, valor e prazos serão validados e poderão sofrer reajustes. | D20: ( I ) | E20: 200 | F20: 1 | G20: 350 | H20: =E20*F20*G20 -> 70000 | K20: 0 | L20: =H20 -> 70000
B21: 2.2 | C21: THE BLEND Cliente é responsável pela disponibilização do material para o manuseio do press kit. | D21: ( I ) | E21: 1 | F21: 1 | G21: 0 | H21: RESPONSABILIDADE CLIENTE | K21: 0 | L21: =H21 -> RESPONSABILIDADE CLIENTE
B22: 3 | C22: EQUIPE | I22: =SUM(H23:H25) -> 0 | K22: À VISTA ANTECIPADO | L22: =L$16 -> 75 DIAS
B23: 3.1 | C23: Atendimento Projeto Período 1 mês, pré produção, execução e pós produção. | D23: ( I ) | E23: 1 | F23: 1 | G23: 0 | H23: CORTESIA | K23: 0 | L23: =H23 -> CORTESIA
B24: 3.2 | C24: Produtor Executivo - VALOR EXCLUSIVO PARA O PROJETO Período 1 mês, pré-produção, execução e pós-produção | D24: ( I ) | E24: 1 | F24: 1 | G24: 0 | H24: CORTESIA | K24: 0 | L24: =H24 -> CORTESIA
B25: 3.3 | C25: Apoio para manuseio | D25: ( I ) | E25: 1 | F25: 1 | G25: 0 | H25: CORTESIA | K25: 0 | L25: =H25 -> CORTESIA
B26: 4 | C26: LOGÍSTICA | I26: =SUM(H27:H32) -> 600 | K26: À VISTA ANTECIPADO | L26: =L$16 -> 75 DIAS
B27: 4.1 | C27: Logística entrega - Kits manuseados - 1º envio Entrega de 50 unidades de sacolas + 50 unidades de carta no dia 16/03/2026 Local de entrega: PSLOG Operações Logística CNPJ: 48.672.078/0001-89 Endereço: Av Onze de Junho, 1070 cj 1307, vila Clementino São Paulo A/C: Luiz *Entrega em horário comercial, de segunda a sexta. *Considerando entrega única no endereço informado. | D27: ( I ) | E27: 1 | F27: 1 | G27: 0 | H27: INCLUSO NO ORÇAMENTO | K27: 0 | L27: =H27 -> INCLUSO NO ORÇAMENTO
B28: 4.2 | C28: Logística entrega - Kits manuseados - 2º envio Entrega de 50 unidades de sacolas + 50 unidades de carta no dia 23/03/2026 Local de entrega: PSLOG Operações Logística CNPJ: 48.672.078/0001-89 Endereço: Av Onze de Junho, 1070 cj 1307, vila Clementino São Paulo A/C: Luiz *Entrega em horário comercial, de segunda a sexta. *Considerando entrega única no endereço informado. | D28: ( I ) | E28: 1 | F28: 1 | G28: 300 | H28: =E28*F28*G28 -> 300 | K28: 0 | L28: =H28 -> 300
B29: 4.3 | C29: Logística entrega - Kits manuseados - 3º envio Entrega de 100 unidades de sacolas + 100 unidades de carta no dia 30/03/2026 Local de entrega: PSLOG Operações Logística CNPJ: 48.672.078/0001-89 Endereço: Av Onze de Junho, 1070 cj 1307, vila Clementino São Paulo A/C: Luiz *Entrega em horário comercial, de segunda a sexta. *Considerando entrega única no endereço informado. | D29: ( I ) | E29: 1 | F29: 1 | G29: 300 | H29: =E29*F29*G29 -> 300 | K29: 0 | L29: =H29 -> 300
B30: 4.4 | C30: Logística equipe manuseio 01 pax x 02 diárias x ida e volta | D30: ( I ) | E30: 1 | F30: 1 | G30: 0 | H30: CORTESIA | K30: 0 | L30: =H30 -> CORTESIA
C31: Logistica Produtos e Materiais - Cliente
B32: 4.5 | C32: Logística de materiais / produtos cliente Logística de materiais e produtos do cliente para utilização no manuseio do kit sendo responsabilidade do cliente e conforme endereço indicado pela agência com base no fornecedor contratado. | D32: ( I ) | E32: 1 | F32: 1 | G32: 0 | H32: RESPONSABILIDADE CLIENTE | K32: 0 | L32: =H32 -> RESPONSABILIDADE CLIENTE
B33: 5 | C33: OUTROS | I33: =SUM(H34:H34) -> 0 | K33: À VISTA ANTECIPADO | L33: =L$16 -> 75 DIAS
B34: 5.1 | C34: Verba de Produção Verba de produção e necessidades emergências de produção. Entrega e retirada de amostras, motoboy, compra de itens, entre outras demandas. *Valores serão apresentados conforme demanda. | D34: ( I ) | E34: 1 | F34: 1 | G34: 0 | H34: A FATURAR EM CASO DE NECESSIDADE | K34: 0 | L34: =H34 -> A FATURAR EM CASO DE NECESSIDADE
H35: SOMA GERAL DOS ITENS | I35: =SUM(I16:I34) -> 75600 | K35: =SUM(K16:K34) -> 0 | L35: =SUM(L16:L34) -> 75600
B36: 01 - SUB-TOTAL - INTERNOS (I) | I36: =SUMIF(D:D,"( I )",H:H) -> 75600
B37: 02 - SUB-TOTAL - TERCEIROS (T) | I37: =SUMIF(D:D,"( T )",H:H) -> 0
B38: 03 - SUB-TOTAL - CRIAÇÃO (C) | I38: =SUMIF(D:D,"( C )",H:H) -> 0
B39: SUB TOTAL GERAL (01 + 02 + 03) | I39: =SUM(I36:I38) -> 75600 | K39: À VISTA ANTECIPADO | L39: =L$16 -> 75 DIAS
B40: PLANEJAMENTO TÁTICO E CRIAÇÃO - SOBRE ITENS INTERNOS (I) E TERCEIROS (T) | H40: 0 | I40: =SUM(I36+I37)*H40 -> 0 | K40: 0 | L40: =I40 -> 0
B41: HONORÁRIOS | H41: 0.1 | I41: =(I36+I37)*H41 -> 7560 | K41: 0 | L41: =I41 -> 7560
B42: ENCARGOS | H42: 16% | I42: =(I36+I38+I40+I41)/(1-H42)-(I36+I38+I40+I41) -> 15840 | K42: 0 | L42: =I42 -> 15840
...

Sheet REF.
