Workbook
Name campo: #REF!
Name campo: #REF!
Name campo: #REF!
Name Campo_Listagem: #REF!
Name Campo_Listagem: #REF!
Name Campo_Listagem: #REF!
Name Conteúdo: #REF!
Name FX_BRLEUR: #REF!
Name hj: #REF!
Name j: #REF!
Name periodo_selecionado: #REF!
Name PeriodoInPlanejado: #REF!=MEDIAN(#REF!,#REF!,#REF!+#REF!-1)
Name PeriodoInReal: #REF!=MEDIAN(#REF!,#REF!,#REF!+#REF!-1)
Name Plano: PeriodoInPlanejado*(#REF!>0)
Name PorcentagemConcluída: PorcentagemConcluídaPosterior*PeriodoInPlanejado
Name PorcentagemConcluídaPosterior: (#REF!=MEDIAN(#REF!,#REF!,#REF!+#REF!)*(#REF!>0))*((#REF!<(INT(#REF!+#REF!*#REF!)))+(#REF!=#REF!))*(#REF!>0)
Name Real: (PeriodoInReal*(#REF!>0))*PeriodoInPlanejado
Name RealPosterior: PeriodoInReal*(#REF!>0)
Name Resuumo: #REF!
Name Status: #REF!

Sheet RESUMO
D1: PLANILHA DE ESTIMATIVA DE CUSTOS
C2: Evento:
C3: Data do Evento:
C4: Horário do Evento:
C5: Data da Montagem:
C6: Qtde Pessoas:
C7: Local:
C8: PIT:
C9: Atendimento:
C10: Pré Produção:
I13: EXCLUIR NA VERSÃO CLIENTE | L13: EXCLUIR NA VERSÃO CLIENTE
B14: RESUMO GERAL | F14: CASHFLOW | I14: RENTABILIDADE _ BRUTO | L14: RENTABILIDADE _ LÍQUIDO
B15: PLANILHA | D15: VALOR | F15: À VISTA ANTECIPADO | G15: 30 DIAS | I15: MARGEM - R$ | J15: % | L15: MARGEM - R$ | M15: %
B16: GERAL | D16: =GERAL!I$428 -> 0 | F16: =GERAL!K$428 -> 0 | G16: =GERAL!L$428 -> 0 | I16: =GERAL!W424 -> 0 | J16: =GERAL!W425 -> #DIV/0! | L16: =GERAL!W427 -> 0 | M16: =GERAL!W428 -> #DIV/0!
D17: =SUM(D16:D16) -> 0 | F17: =SUM(F16:F16) -> 0 | G17: =SUM(G16:G16) -> 0
C20: BUDGET

Sheet GERAL
I2: PLANILHA DE ESTIMATIVA DE CUSTOS
H3: Evento: | I3: =RESUMO!D2 -> 0
H4: Data do Evento: | I4: =RESUMO!D3 -> 0
H5: Horário do Evento: | I5: =RESUMO!D4 -> 0
H6: Data da Montagem: | I6: =RESUMO!D5 -> 0
H7: Qtde Pessoas: | I7: =RESUMO!D6 -> 0
H8: Local: | I8: =RESUMO!D7 -> 0
H9: PIT: | I9: =RESUMO!D8 -> 0
H10: Atendimento: | I10: =RESUMO!D9 -> 0 | V10: TAXA BANCÁRIA POR MÊS | W10: 0.02 | AG10: TAXA BANCÁRIA POR MÊS
H11: Pré Produção: | I11: =RESUMO!D10 -> 0 | V11: VERIFICAR COM ATENDIMENTO COMO SERÁ COBRADO, DEPENDENDO DO CLIENTE
AG12: NÃO SE APLICA HONORÁRIOS
I13: =I428 -> 0
B14: ITEM | C14: DESCRIÇÃO | D14: INTERNO (I) TERCEIRO (T) CRIAÇÃO (C) | E14: QUANT | F14: UNIDADE | G14: VALOR UNIT | H14: VALOR TOTAL | I14: SUBTOTAL | K14: CASHFLOW | P14: Orçamentos | T14: PRÉ PRODUÇÃO | AC14: PRODUÇÃO
B15: 1 | C15: CRIAÇÃO E FINALIZAÇÃO | I15: =SUM(H16:H25) -> 0 | K15: À VISTA ANTECIPADO | L15: =RESUMO!G$15 -> 30 DIAS | P15: ORÇAMENTO 1 | Q15: ORÇAMENTO 2 | R15: ORÇAMENTO 3 | T15: FORNECEDOR | U15: CUSTO REAL | V15: TAXA BANCÁRIA | W15: SOBRA | X15: DEDUÇÃO DE IMPOSTO (FORNECEDOR) | Z15: PDI | AA15: TOTAL (SOBRA + PDI) | AC15: STATUS PRODUÇÃO | AD15: LINHA OC | AE15: FORNECEDOR | AF15: CUSTO REAL | AG15: TAXA BANCÁRIA | AH15: SOBRA | AI15: PDI | AJ15: TOTAL (SOBRA + PDI) | AK15: FECHAR ITEM | AL15: PRECISA DE NOTA DE COBERTURA? | AM15: DEDUÇÃO DE IMPOSTO (FORNECEDOR) | AO15: CÓDIGO FORNECEDOR - PUBLI | AP15: VENCIMENTO | AQ15: AUTORIZAÇÃO DE PRODUÇÃO ENVIADO
B16: 1.1 | C16: Desenvolvimento do KV e Conceito Criação e finalização. | D16: ( C ) | E16: 1 | F16: 1 | G16: 0 | H16: =E16*F16*G16 -> 0 | K16: 0 | L16: =H16 -> 0 | U16: 0 | V16: 0 | W16: =(H16-U16)-V16 -> 0 | X16: 1 | Y16: =W16-(W16*X16) -> 0 | Z16: =U16*0% -> 0 | AA16: =(W16+Z16)-Y16 -> 0 | AD16: =B16 -> 1.1 | AE16: =T16 -> 0 | AF16: =U16 -> 0 | AG16: 0 | AH16: =H16-AF16 -> 0 | AI16: =AF16*10% -> 0 | AJ16: =AN16+AI16 -> 0 | AK16: NÃO | AL16: NÃO | AM16: 0 | AN16: =(AH16-(AH16*AM16)) -> 0 | AP16: 0
B17: 1.2 | C17: Compra de imagens - VALIDAR COM CRIAÇÃO + ATENDIMENTO!!!!!!! A ser avaliado conforme desenvolvimento das peças. Valores apresentados posteriormente. | D17: ( I ) | E17: 1 | F17: 1 | G17: 0 | H17: =E17*F17*G17 -> 0 | K17: 0 | L17: =H17 -> 0 | U17: 0 | V17: 0 | W17: =(H17-U17)-V17 -> 0 | X17: 1 | Y17: =W17-(W17*X17) -> 0 | Z17: =U17*0% -> 0 | AA17: =(W17+Z17)-Y17 -> 0 | AD17: =B17 -> 1.2 | AE17: =T17 -> 0 | AF17: =U17 -> 0 | AG17: 0 | AH17: =H17-AF17 -> 0 | AI17: =AF17*10% -> 0 | AJ17: =AN17+AI17 -> 0 | AK17: NÃO | AL17: NÃO | AM17: 0 | AN17: =(AH17-(AH17*AM17)) -> 0 | AP17: 0
B18: 1.3 | C18: Peças de Comunicação Digital Criação e finalização das peças: Teaser, Save the date, convite, reminder 1 , reminder 2 e agradecimento. | D18: ( C ) | E18: 1 | F18: 1 | G18: 0 | H18: =E18*F18*G18 -> 0 | K18: 0 | L18: =H18 -> 0 | U18: 0 | V18: 0 | W18: =(H18-U18)-V18 -> 0 | X18: 1 | Y18: =W18-(W18*X18) -> 0 | Z18: =U18*0% -> 0 | AA18: =(W18+Z18)-Y18 -> 0 | AD18: =B18 -> 1.3 | AE18: =T18 -> 0 | AF18: =U18 -> 0 | AG18: 0 | AH18: =H18-AF18 -> 0 | AI18: =AF18*10% -> 0 | AJ18: =AN18+AI18 -> 0 | AK18: NÃO | AL18: NÃO | AM18: 0 | AN18: =(AH18-(AH18*AM18)) -> 0 | AP18: 0
B19: 1.4 | C19: Cenografia Criação e finalização de peças utilizadas na cenografia do evento. | D19: ( C ) | E19: 1 | F19: 1 | G19: 0 | H19: =E19*F19*G19 -> 0 | K19: 0 | L19: =H19 -> 0 | U19: 0 | V19: 0 | W19: =(H19-U19)-V19 -> 0 | X19: 1 | Y19: =W19-(W19*X19) -> 0 | Z19: =U19*0% -> 0 | AA19: =(W19+Z19)-Y19 -> 0 | AD19: =B19 -> 1.4 | AE19: =T19 -> 0 | AF19: =U19 -> 0 | AG19: 0 | AH19: =H19-AF19 -> 0 | AI19: =AF19*10% -> 0 | AJ19: =AN19+AI19 -> 0 | AK19: NÃO | AL19: NÃO | AM19: 0 | AN19: =(AH19-(AH19*AM19)) -> 0 | AP19: 0
B20: 1.5 | C20: Projeto Arquitetônico Projeto Arquitetônico / Design e Desenvolvimento em 3D | D20: ( C ) | E20: 1 | F20: 1 | G20: 0 | H20: =E20*F20*G20 -> 0 | K20: 0 | L20: =H20 -> 0 | U20: 0 | V20: 0 | W20: =(H20-U20)-V20 -> 0 | X20: 1 | Y20: =W20-(W20*X20) -> 0 | Z20: =U20*0% -> 0 | AA20: =(W20+Z20)-Y20 -> 0 | AD20: =B20 -> 1.5 | AE20: =T20 -> 0 | AF20: =U20 -> 0 | AG20: 0 | AH20: =H20-AF20 -> 0 | AI20: =AF20*10% -> 0 | AJ20: =AN20+AI20 -> 0 | AK20: NÃO | AL20: NÃO | AM20: 0 | AN20: =(AH20-(AH20*AM20)) -> 0 | AP20: 0
B21: 1.6 | C21: Template Criação e finalização de template para as apresentações. | D21: ( C ) | E21: 1 | F21: 1 | G21: 0 | H21: =E21*F21*G21 -> 0 | K21: 0 | L21: =H21 -> 0 | U21: 0 | V21: 0 | W21: =(H21-U21)-V21 -> 0 | X21: 1 | Y21: =W21-(W21*X21) -> 0 | Z21: =U21*0% -> 0 | AA21: =(W21+Z21)-Y21 -> 0 | AD21: =B21 -> 1.6 | AE21: =T21 -> 0 | AF21: =U21 -> 0 | AG21: 0 | AH21: =H21-AF21 -> 0 | AI21: =AF21*10% -> 0 | AJ21: =AN21+AI21 -> 0 | AK21: NÃO | AL21: NÃO | AM21: 0 | AN21: =(AH21-(AH21*AM21)) -> 0 | AP21: 0
B22: 1.7 | C22: Materiais Criação e finalização de brindes, uniforme e impressos | D22: ( C ) | E22: 1 | F22: 1 | G22: 0 | H22: =E22*F22*G22 -> 0 | K22: 0 | L22: =H22 -> 0 | U22: 0 | V22: 0 | W22: =(H22-U22)-V22 -> 0 | X22: 1 | Y22: =W22-(W22*X22) -> 0 | Z22: =U22*0% -> 0 | AA22: =(W22+Z22)-Y22 -> 0 | AD22: =B22 -> 1.7 | AE22: =T22 -> 0 | AF22: =U22 -> 0 | AG22: 0 | AH22: =H22-AF22 -> 0 | AI22: =AF22*10% -> 0 | AJ22: =AN22+AI22 -> 0 | AK22: NÃO | AL22: NÃO | AM22: 0 | AN22: =(AH22-(AH22*AM22)) -> 0 | AP22: 0
B23: 1.8 | C23: Retoque e/ou Tratamento de imagem | D23: ( C ) | E23: 1 | F23: 1 | G23: 0 | H23: =E23*F23*G23 -> 0 | K23: 0 | L23: =H23 -> 0 | U23: 0 | V23: 0 | W23: =(H23-U23)-V23 -> 0 | X23: 1 | Y23: =W23-(W23*X23) -> 0 | Z23: =U23*0% -> 0 | AA23: =(W23+Z23)-Y23 -> 0 | AD23: =B23 -> 1.8 | AE23: =T23 -> 0 | AF23: =U23 -> 0 | AG23: 0 | AH23: =H23-AF23 -> 0 | AI23: =AF23*10% -> 0 | AJ23: =AN23+AI23 -> 0 | AK23: NÃO | AL23: NÃO | AM23: 0 | AN23: =(AH23-(AH23*AM23)) -> 0 | AP23: 0
B24: 1.9 | C24: Ilustrações | D24: ( C ) | E24: 1 | F24: 1 | G24: 0 | H24: =E24*F24*G24 -> 0 | K24: 0 | L24: =H24 -> 0 | U24: 0 | V24: 0 | W24: =(H24-U24)-V24 -> 0 | X24: 1 | Y24: =W24-(W24*X24) -> 0 | Z24: =U24*0% -> 0 | AA24: =(W24+Z24)-Y24 -> 0 | AD24: =B24 -> 1.9 | AE24: =T24 -> 0 | AF24: =U24 -> 0 | AG24: 0 | AH24: =H24-AF24 -> 0 | AI24: =AF24*10% -> 0 | AJ24: =AN24+AI24 -> 0 | AK24: NÃO | AL24: NÃO | AM24: 0 | AN24: =(AH24-(AH24*AM24)) -> 0 | AP24: 0
B25: 1.10 | C25: Logo, elementos da marca e banco de imagens Disponibilidade de materiais gerais para realização do trabalho. | D25: ( T ) | E25: 1 | F25: 1 | G25: 0 | H25: RESPONSABILIDADE CLIENTE | K25: 0 | L25: =H25 -> RESPONSABILIDADE CLIENTE | T25: =L25 -> RESPONSABILIDADE CLIENTE | U25: 0 | V25: 0 | W25: 0 | X25: 1 | Y25: =W25-(W25*X25) -> 0 | Z25: =U25*0% -> 0 | AA25: =(W25+Z25)-Y25 -> 0 | AD25: =B25 -> 1.10 | AE25: =T25 -> RESPONSABILIDADE CLIENTE | AF25: =U25 -> 0 | AG25: 0 | AI25: =AF25*10% -> 0 | AJ25: =AN25+AI25 -> 0 | AK25: NÃO | AL25: NÃO | AM25: 0 | AN25: =(AH25-(AH25*AM25)) -> 0 | AP25: 0
B26: 2 | C26: COMUNICAÇÃO / RSVP / CREDENCIAMENTO | I26: =SUM(H27:H42) -> 0 | K26: À VISTA ANTECIPADO | L26: =L$15 -> 30 DIAS | P26: ORÇAMENTO 1 | Q26: ORÇAMENTO 2 | R26: ORÇAMENTO 3 | T26: FORNECEDOR | U26: CUSTO REAL | V26: TAXA BANCÁRIA | W26: SOBRA | X26: DEDUÇÃO DE IMPOSTO (FORNECEDOR) | Z26: PDI | AA26: TOTAL (SOBRA + PDI) | AC26: STATUS PRODUÇÃO | AD26: LINHA OC | AE26: FORNECEDOR | AF26: CUSTO REAL | AG26: TAXA BANCÁRIA | AH26: SOBRA | AI26: PDI | AJ26: TOTAL (SOBRA + PDI) | AK26: FECHAR ITEM | AL26: PRECISA DE NOTA DE COBERTURA? | AM26: DEDUÇÃO DE IMPOSTO (FORNECEDOR) | AO26: CÓDIGO FORNECEDOR - PUBLI | AP26: VENCIMENTO | AQ26: AUTORIZAÇÃO DE PRODUÇÃO ENVIADO
B27: 2.1 | C27: Mailing dos participantes Relação dos participantes do evento com a validação de suas presenças e dados necessários que serão alinhados no processo de produção do evento. | D27: ( T ) | E27: 1 | F27: 1 | G27: 0 | H27: RESPONSABILIDADE CLIENTE | K27: 0 | L27: =H27 -> RESPONSABILIDADE CLIENTE | T27: =L27 -> RESPONSABILIDADE CLIENTE | U27: 0 | V27: 0 | W27: 0 | X27: 1 | Y27: =W27-(W27*X27) -> 0 | Z27: =U27*10% -> 0 | AA27: =(W27+Z27)-Y27 -> 0 | AD27: =B27 -> 2.1 | AE27: =T27 -> RESPONSABILIDADE CLIENTE | AF27: =U27 -> 0 | AG27: 0 | AI27: =AF27*10% -> 0 | AJ27: =AN27+AI27 -> 0 | AK27: NÃO | AL27: NÃO | AM27: 0 | AN27: =(AH27-(AH27*AM27)) -> 0 | AP27: 0
B28: 2.2 | C28: Clean-up do mailing Prazo para recebimento: Valor sujeito a alteração sem aviso prévio. Caso o recebimento aconteça após a data sinalizado, valores poderão sofrer ajuste. Validade da proposta: XX dias à partir de xx/xx/xx. | D28: ( I ) | E28: 1 | F28: 1 | G28: 0 | H28: =E28*F28*G28 -> 0 | K28: 0 | L28: =H28 -> 0 | U28: 0 | V28: 0 | W28: =(H28-U28)-V28 -> 0 | X28: 1 | Y28: =W28-(W28*X28) -> 0 | Z28: =U28*10% -> 0 | AA28: =(W28+Z28)-Y28 -> 0 | AD28: =B28 -> 2.2 | AE28: =T28 -> 0 | AF28: =U28 -> 0 | AG28: 0 | AH28: =H28-AF28 -> 0 | AI28: =AF28*10% -> 0 | AJ28: =AN28+AI28 -> 0 | AK28: NÃO | AL28: NÃO | AM28: 0 | AN28: =(AH28-(AH28*AM28)) -> 0 | AP28: 0
B29: 2.3 | C29: Disparo de E-mail Marketing Prazo para aprovação: Prazo para configurações de sistema: Valor sujeito a alteração sem aviso prévio. Caso a aprovação aconteça após a data sinalizado, valores poderão sofrer ajuste. Validade da proposta: XX dias à partir de xx/xx/xx. | D29: ( I ) | E29: 1 | F29: 1 | G29: 0 | H29: =E29*F29*G29 -> 0 | K29: 0 | L29: =H29 -> 0 | U29: 0 | V29: 0 | W29: =(H29-U29)-V29 -> 0 | X29: 1 | Y29: =W29-(W29*X29) -> 0 | Z29: =U29*10% -> 0 | AA29: =(W29+Z29)-Y29 -> 0 | AD29: =B29 -> 2.3 | AE29: =T29 -> 0 | AF29: =U29 -> 0 | AG29: 0 | AH29: =H29-AF29 -> 0 | AI29: =AF29*10% -> 0 | AJ29: =AN29+AI29 -> 0 | AK29: NÃO | AL29: NÃO | AM29: 0 | AN29: =(AH29-(AH29*AM29)) -> 0 | AP29: 0
B30: 2.4 | C30: Disparo de Whatsapp Prazo para aprovação: Prazo para configurações de sistema: Valor sujeito a alteração sem aviso prévio. Caso a aprovação aconteça após a data sinalizado, valores poderão sofrer ajuste. Validade da proposta: XX dias à partir de xx/xx/xx. | D30: ( I ) | E30: 1 | F30: 1 | G30: 0 | H30: =E30*F30*G30 -> 0 | K30: 0 | L30: =H30 -> 0 | U30: 0 | V30: 0 | W30: =(H30-U30)-V30 -> 0 | X30: 1 | Y30: =W30-(W30*X30) -> 0 | Z30: =U30*10% -> 0 | AA30: =(W30+Z30)-Y30 -> 0 | AD30: =B30 -> 2.4 | AE30: =T30 -> 0 | AF30: =U30 -> 0 | AG30: 0 | AH30: =H30-AF30 -> 0 | AI30: =AF30*10% -> 0 | AJ30: =AN30+AI30 -> 0 | AK30: NÃO | AL30: NÃO | AM30: 0 | AN30: =(AH30-(AH30*AM30)) -> 0 | AP30: 0
B31: 2.5 | C31: Disparo de SMS Prazo para aprovação: Prazo para configurações de sistema: Valor sujeito a alteração sem aviso prévio. Caso a aprovação aconteça após a data sinalizado, valores poderão sofrer ajuste. Validade da proposta: XX dias à partir de xx/xx/xx. | D31: ( I ) | E31: 1 | F31: 1 | G31: 0 | H31: =E31*F31*G31 -> 0 | K31: 0 | L31: =H31 -> 0 | U31: 0 | V31: 0 | W31: =(H31-U31)-V31 -> 0 | X31: 1 | Y31: =W31-(W31*X31) -> 0 | Z31: =U31*10% -> 0 | AA31: =(W31+Z31)-Y31 -> 0 | AD31: =B31 -> 2.5 | AE31: =T31 -> 0 | AF31: =U31 -> 0 | AG31: 0 | AH31: =H31-AF31 -> 0 | AI31: =AF31*10% -> 0 | AJ31: =AN31+AI31 -> 0 | AK31: NÃO | AL31: NÃO | AM31: 0 | AN31: =(AH31-(AH31*AM31)) -> 0 | AP31: 0
B32: 2.6 | C32: Chatbot Prazo para aprovação: Prazo para configurações de sistema: Valor sujeito a alteração sem aviso prévio. Caso a aprovação aconteça após a data sinalizado, valores poderão sofrer ajuste. Validade da proposta: XX dias à partir de xx/xx/xx. | D32: ( I ) | E32: 1 | F32: 1 | G32: 0 | H32: =E32*F32*G32 -> 0 | K32: 0 | L32: =H32 -> 0 | U32: 0 | V32: 0 | W32: =(H32-U32)-V32 -> 0 | X32: 1 | Y32: =W32-(W32*X32) -> 0 | Z32: =U32*10% -> 0 | AA32: =(W32+Z32)-Y32 -> 0 | AD32: =B32 -> 2.6 | AE32: =T32 -> 0 | AF32: =U32 -> 0 | AG32: 0 | AH32: =H32-AF32 -> 0 | AI32: =AF32*10% -> 0 | AJ32: =AN32+AI32 -> 0 | AK32: NÃO | AL32: NÃO | AM32: 0 | AN32: =(AH32-(AH32*AM32)) -> 0 | AP32: 0
B33: 2.7 | C33: PA - Serviço Ativo Prazo para aprovação: Prazo para configurações de sistema: Valor sujeito a alteração sem aviso prévio. Caso a aprovação aconteça após a data sinalizado, valores poderão sofrer ajuste. Validade da proposta: XX dias à partir de xx/xx/xx. | D33: ( I ) | E33: 1 | F33: 1 | G33: 0 | H33: =E33*F33*G33 -> 0 | K33: 0 | L33: =H33 -> 0 | U33: 0 | V33: 0 | W33: =(H33-U33)-V33 -> 0 | X33: 1 | Y33: =W33-(W33*X33) -> 0 | Z33: =U33*10% -> 0 | AA33: =(W33+Z33)-Y33 -> 0 | AD33: =B33 -> 2.7 | AE33: =T33 -> 0 | AF33: =U33 -> 0 | AG33: 0 | AH33: =H33-AF33 -> 0 | AI33: =AF33*10% -> 0 | AJ33: =AN33+AI33 -> 0 | AK33: NÃO | AL33: NÃO | AM33: 0 | AN33: =(AH33-(AH33*AM33)) -> 0 | AP33: 0
B34: 2.8 | C34: PA - Serviço Receptivo Prazo para aprovação: Prazo para configurações de sistema: Valor sujeito a alteração sem aviso prévio. Caso a aprovação aconteça após a data sinalizado, valores poderão sofrer ajuste. Validade da proposta: XX dias à partir de xx/xx/xx. | D34: ( I ) | E34: 1 | F34: 1 | G34: 0 | H34: =E34*F34*G34 -> 0 | K34: 0 | L34: =H34 -> 0 | U34: 0 | V34: 0 | W34: =(H34-U34)-V34 -> 0 | X34: 1 | Y34: =W34-(W34*X34) -> 0 | Z34: =U34*10% -> 0 | AA34: =(W34+Z34)-Y34 -> 0 | AD34: =B34 -> 2.8 | AE34: =T34 -> 0 | AF34: =U34 -> 0 | AG34: 0 | AH34: =H34-AF34 -> 0 | AI34: =AF34*10% -> 0 | AJ34: =AN34+AI34 -> 0 | AK34: NÃO | AL34: NÃO | AM34: 0 | AN34: =(AH34-(AH34*AM34)) -> 0 | AP34: 0
B35: 2.9 | C35: Serviço Chatbot Prazo para aprovação: Prazo para configurações de sistema: Valor sujeito a alteração sem aviso prévio. Caso a aprovação aconteça após a data sinalizado, valores poderão sofrer ajuste. Validade da proposta: XX dias à partir de xx/xx/xx. | D35: ( I ) | E35: 1 | F35: 1 | G35: 0 | H35: =E35*F35*G35 -> 0 | K35: 0 | L35: =H35 -> 0 | U35: 0 | V35: 0 | W35: =(H35-U35)-V35 -> 0 | X35: 1 | Y35: =W35-(W35*X35) -> 0 | Z35: =U35*10% -> 0 | AA35: =(W35+Z35)-Y35 -> 0 | AD35: =B35 -> 2.9 | AE35: =T35 -> 0 | AF35: =U35 -> 0 | AG35: 0 | AH35: =H35-AF35 -> 0 | AI35: =AF35*10% -> 0 | AJ35: =AN35+AI35 -> 0 | AK35: NÃO | AL35: NÃO | AM35: 0 | AN35: =(AH35-(AH35*AM35)) -> 0 | AP35: 0
B36: 2.10 | C36: E-mail de agradecimento Prazo para aprovação: Prazo para configurações de sistema: Valor sujeito a alteração sem aviso prévio. Caso a aprovação aconteça após a data sinalizado, valores poderão sofrer ajuste. Validade da proposta: XX dias à partir de xx/xx/xx. | D36: ( I ) | E36: 1 | F36: 1 | G36: 0 | H36: =E36*F36*G36 -> 0 | K36: 0 | L36: =H36 -> 0 | U36: 0 | V36: 0 | W36: =(H36-U36)-V36 -> 0 | X36: 1 | Y36: =W36-(W36*X36) -> 0 | Z36: =U36*10% -> 0 | AA36: =(W36+Z36)-Y36 -> 0 | AD36: =B36 -> 2.10 | AE36: =T36 -> 0 | AF36: =U36 -> 0 | AG36: 0 | AH36: =H36-AF36 -> 0 | AI36: =AF36*10% -> 0 | AJ36: =AN36+AI36 -> 0 | AK36: NÃO | AL36: NÃO | AM36: 0 | AN36: =(AH36-(AH36*AM36)) -> 0 | AP36: 0
B37: 2.11 | C37: Pesquisa de Satisfação Prazo para aprovação: Prazo para configurações de sistema: Valor sujeito a alteração sem aviso prévio. Caso a aprovação aconteça após a data sinalizado, valores poderão sofrer ajuste. Validade da proposta: XX dias à partir de xx/xx/xx. | D37: ( I ) | E37: 1 | F37: 1 | G37: 0 | H37: =E37*F37*G37 -> 0 | K37: 0 | L37: =H37 -> 0 | U37: 0 | V37: 0 | W37: =(H37-U37)-V37 -> 0 | X37: 1 | Y37: =W37-(W37*X37) -> 0 | Z37: =U37*10% -> 0 | AA37: =(W37+Z37)-Y37 -> 0 | AD37: =B37 -> 2.11 | AE37: =T37 -> 0 | AF37: =U37 -> 0 | AG37: 0 | AH37: =H37-AF37 -> 0 | AI37: =AF37*10% -> 0 | AJ37: =AN37+AI37 -> 0 | AK37: NÃO | AL37: NÃO | AM37: 0 | AN37: =(AH37-(AH37*AM37)) -> 0 | AP37: 0
B38: 2.12 | C38: Hotsite / Landingpage / APP Prazo de produção: XX dias úteis à partir do recebimento da AF considerando a realziação de testes e validações de segurança. Valor sujeito a alteração sem aviso prévio. Caso a aprovação aconteça após a data sinalizado, valores poderão sofrer ajuste. Validade da proposta: XX dias à partir de xx/xx/xx. | D38: ( I ) | E38: 1 | F38: 1 | G38: 0 | H38: =E38*F38*G38 -> 0 | K38: 0 | L38: =H38 -> 0 | U38: 0 | V38: 0 | W38: =(H38-U38)-V38 -> 0 | X38: 1 | Y38: =W38-(W38*X38) -> 0 | Z38: =U38*10% -> 0 | AA38: =(W38+Z38)-Y38 -> 0 | AD38: =B38 -> 2.12 | AE38: =T38 -> 0 | AF38: =U38 -> 0 | AG38: 0 | AH38: =H38-AF38 -> 0 | AI38: =AF38*10% -> 0 | AJ38: =AN38+AI38 -> 0 | AK38: NÃO | AL38: NÃO | AM38: 0 | AN38: =(AH38-(AH38*AM38)) -> 0 | AP38: 0
B39: 2.13 | C39: QR Code Prazo de produção: XX dias úteis à partir do recebimento do link para direcionamento. Valor sujeito a alteração sem aviso prévio. Caso a aprovação e o recebimento do link aconteçam após a data sinalizado, valores poderão sofrer ajuste. Validade da proposta: XX dias à partir de xx/xx/xx. | D39: ( I ) | E39: 1 | F39: 1 | G39: 0 | H39: =E39*F39*G39 -> 0 | K39: 0 | L39: =H39 -> 0 | U39: 0 | V39: 0 | W39: =(H39-U39)-V39 -> 0 | X39: 1 | Y39: =W39-(W39*X39) -> 0 | Z39: =U39*10% -> 0 | AA39: =(W39+Z39)-Y39 -> 0 | AD39: =B39 -> 2.13 | AE39: =T39 -> 0 | AF39: =U39 -> 0 | AG39: 0 | AH39: =H39-AF39 -> 0 | AI39: =AF39*10% -> 0 | AJ39: =AN39+AI39 -> 0 | AK39: NÃO | AL39: NÃO | AM39: 0 | AN39: =(AH39-(AH39*AM39)) -> 0 | AP39: 0
... B42: 2.16 | C42: Promotoras Credenciamento Prazo para aprovação: Valor sujeito a alteração sem aviso prévio. Caso a aprovação aconteça após a data sinalizado, valores poderão sofrer ajuste. Validade da proposta: XX dias à partir de xx/xx/xx. | D42: ( I ) | E42: 1 | F42: 1 | G42: 0 | H42: =E42*F42*G42 -> 0 | K42: 0 | L42: =H42 -> 0 | U42: 0 | V42: 0 | W42: =(H42-U42)-V42 -> 0 | X42: 1 | Y42: =W42-(W42*X42) -> 0 | Z42: =U42*10% -> 0 | AA42: =(W42+Z42)-Y42 -> 0 | AD42: =B42 -> 2.16 | AE42: =T42 -> 0 | AF42: =U42 -> 0 | AG42: 0 | AH42: =H42-AF42 -> 0 | AI42: =AF42*10% -> 0 | AJ42: =AN42+AI42 -> 0 | AK42: NÃO | AL42: NÃO | AM42: 0 | AN42: =(AH42-(AH42*AM42)) -> 0 | AP42: 0
B43: 3 | C43: ESPAÇOS | I43: =SUM(H44:H54) -> 0 | K43: À VISTA ANTECIPADO | L43: =L$15 -> 30 DIAS | P43: ORÇAMENTO 1 | Q43: ORÇAMENTO 2 | R43: ORÇAMENTO 3 | T43: FORNECEDOR | U43: CUSTO REAL | V43: TAXA BANCÁRIA | W43: SOBRA | X43: DEDUÇÃO DE IMPOSTO (FORNECEDOR) | Z43: PDI | AA43: TOTAL (SOBRA + PDI) | AC43: STATUS PRODUÇÃO | AD43: LINHA OC | AE43: FORNECEDOR | AF43: CUSTO REAL | AG43: TAXA BANCÁRIA | AH43: SOBRA | AI43: PDI | AJ43: TOTAL (SOBRA + PDI) | AK43: FECHAR ITEM | AL43: PRECISA DE NOTA DE COBERTURA? | AM43: DEDUÇÃO DE IMPOSTO (FORNECEDOR) | AO43: CÓDIGO FORNECEDOR - PUBLI | AP43: VENCIMENTO | AQ43: AUTORIZAÇÃO DE PRODUÇÃO ENVIADO
...

Sheet GRADE
C8: MONTAGEM | G8: EVENTO | K8: DESMONTAGEM
C9: SEG | D9: TER | E9: QUA | F9: QUI | G9: SEX | H9: SAB | I9: DOM | J9: SEG | K9: TER | L9: QUA | M9: QUI | N9: TOTAL
B10: LIMPEZA | C10: 45505 | D10: 45506 | E10: 45507 | F10: 45508 | G10: 45509 | H10: 45510 | I10: 45511 | J10: 45512 | K10: 45513 | L10: 45514 | M10: 45515
B11: 08h00 as 20h00 | N11: =SUM(C11:M11) -> 0
B12: 10h00 as 22h00 | N12: =SUM(C12:M12) -> 0
B13: 13h00 as 01h00 | N13: =SUM(C13:M13) -> 0
B14: 20h00 as 08h00 | N14: =SUM(C14:M14) -> 0
N15: =SUM(N11:N14) -> 0
C19: MONTAGEM | G19: EVENTO | K19: DESMONTAGEM
C20: SEG | D20: TER | E20: QUA | F20: QUI | G20: SEX | H20: SAB | I20: DOM | J20: SEG | K20: TER | L20: QUA | M20: QUI | N20: TOTAL
B21: SEGURANÇA | C21: 45505 | D21: 45506 | E21: 45507 | F21: 45508 | G21: 45509 | H21: 45510 | I21: 45511 | J21: 45512 | K21: 45513 | L21: 45514 | M21: 45515
B22: 08h00 as 20h00 | N22: =SUM(C22:M22) -> 0
B23: 10h00 as 22h00 | N23: =SUM(C23:M23) -> 0
B24: 13h00 as 01h00 | N24: =SUM(C24:M24) -> 0
B25: 20h00 as 08h00 | N25: =SUM(C25:M25) -> 0
N26: =SUM(N22:N25) -> 0
C30: MONTAGEM | G30: EVENTO | K30: DESMONTAGEM
C31: SEG | D31: TER | E31: QUA | F31: QUI | G31: SEX | H31: SAB | I31: DOM | J31: SEG | K31: TER | L31: QUA | M31: QUI | N31: TOTAL
B32: CARREGADORES | C32: 45505 | D32: 45506 | E32: 45507 | F32: 45508 | G32: 45509 | H32: 45510 | I32: 45511 | J32: 45512 | K32: 45513 | L32: 45514 | M32: 45515
B33: 08h00 as 20h00 | N33: =SUM(C33:M33) -> 0
B34: 10h00 as 22h00 | N34: =SUM(C34:M34) -> 0
B35: 13h00 as 01h00 | N35: =SUM(C35:M35) -> 0
B36: 20h00 as 08h00 | N36: =SUM(C36:M36) -> 0
N37: =SUM(N33:N36) -> 0
C41: MONTAGEM | G41: EVENTO | K41: DESMONTAGEM
C42: SEG | D42: TER | E42: QUA | F42: QUI | G42: SEX | H42: SAB | I42: DOM | J42: SEG | K42: TER | L42: QUA | M42: QUI | N42: TOTAL
B43: BRIGADISTAS | C43: 45505 | D43: 45506 | E43: 45507 | F43: 45508 | G43: 45509 | H43: 45510 | I43: 45511 | J43: 45512 | K43: 45513 | L43: 45514 | M43: 45515
B44: 08h00 as 20h00 | N44: =SUM(C44:M44) -> 0
B45: 10h00 as 22h00 | N45: =SUM(C45:M45) -> 0
B46: 13h00 as 01h00 | N46: =SUM(C46:M46) -> 0
B47: 20h00 as 08h00 | N47: =SUM(C47:M47) -> 0
N48: =SUM(N44:N47) -> 0
C51: MONTAGEM | G51: EVENTO | K51: DESMONTAGEM
C52: SEG | D52: TER | E52: QUA | F52: QUI | G52: SEX | H52: SAB | I52: DOM | J52: SEG | K52: TER | L52: QUA | M52: QUI | N52: TOTAL
B53: AMBULÂNCIA SIMPLES | C53: 45505 | D53: 45506 | E53: 45507 | F53: 45508 | G53: 45509 | H53: 45510 | I53: 45511 | J53: 45512 | K53: 45513 | L53: 45514 | M53: 45515
B54: 08h00 as 20h00 | N54: =SUM(C54:M54) -> 0
B55: 10h00 as 22h00 | N55: =SUM(C55:M55) -> 0
B56: 13h00 as 01h00 | N56: =SUM(C56:M56) -> 0
B57: 20h00 as 08h00 | N57: =SUM(C57:M57) -> 0
N58: =SUM(N54:N57) -> 0
...

Sheet CRONOGRAMA
C8: Última atualização em: | D8: =TODAY() -> 46196 | J8: qua | K8: qui | L8: sex | M8: sáb | N8: dom | O8: seg | P8: ter | Q8: qua | R8: qui | S8: sex | T8: sáb | U8: dom | V8: seg | W8: ter | X8: qua | Y8: qui | Z8: sex | AA8: sáb | AB8: dom | AC8: seg | AD8: ter | AE8: qua | AF8: qui | AG8: sex | AH8: sáb | AI8: dom | AJ8: seg | AK8: ter | AL8: qua | AM8: qui | AN8: sex | AO8: sáb | AP8: dom | AQ8: seg | AR8: ter | AS8: qua | AT8: qui | AU8: sex | AV8: sáb | AW8: dom | AX8: seg | AY8: ter | AZ8: qua | BA8: qui | BB8: sex | BC8: sáb | BD8: dom | BE8: seg | BF8: ter | BG8: qua | BH8: qui | BI8: sex | BJ8: sáb | BK8: dom | BL8: seg | BM8: ter | BN8: qua | BO8: qui | BP8: sex | BQ8: sáb | BR8: dom | BS8: seg | BT8: ter | BU8: qua | BV8: qui | BW8: sex | BX8: sáb | BY8: dom | BZ8: seg | CA8: ter | CB8: qua | CC8: qui | CD8: sex | CE8: sáb | CF8: dom | CG8: seg | CH8: ter | CI8: qua | CJ8: qui | CK8: sex | CL8: sáb | CM8: dom | CN8: seg | CO8: ter | CP8: qua | CQ8: qui | CR8: sex | CS8: sáb | CT8: dom | CU8: seg | CV8: ter | CW8: qua | CX8: qui | CY8: sex | CZ8: sáb | DA8: dom | DB8: seg | DC8: ter | DD8: qua | DE8: qui | DF8: sex | DG8: sáb | DH8: dom | DI8: seg | DJ8: ter | DK8: qua | DL8: qui | DM8: sex | DN8: sáb | DO8: dom | DP8: seg | DQ8: ter | DR8: qua | DS8: qui | DT8: sex | DU8: sáb | DV8: dom | DW8: seg | DX8: ter | DY8: qua | DZ8: qui | EA8: sex | EB8: sáb | EC8: dom | ED8: seg | EE8: ter | EF8: qua | EG8: qui | EH8: sex | EI8: sáb | EJ8: dom | EK8: seg | EL8: ter | EM8: qua | EN8: qui | EO8: sex | EP8: sáb | EQ8: dom | ER8: seg | ES8: ter | ET8: qua | EU8: qui | EV8: sex | EW8: sáb | EX8: dom | EY8: seg | EZ8: ter | FA8: qua | FB8: qui | FC8: sex | FD8: sáb | FE8: dom | FF8: seg | FG8: ter | FH8: qua | FI8: qui | FJ8: sex | FK8: sáb | FL8: dom | FM8: seg | FN8: ter | FO8: qua | FP8: qui | FQ8: sex | FR8: sáb | FS8: dom | FT8: seg | FU8: ter | FV8: qua | FW8: qui | FX8: sex | FY8: sáb | FZ8: dom | GA8: seg | GB8: ter | GC8: qua | GD8: qui | GE8: sex | GF8: sáb | GG8: dom | GH8: seg | GI8: ter | GJ8: qua | GK8: qui | GL8: sex | GM8: sáb | GN8: dom | GO8: seg | GP8: ter | GQ8: qua | GR8: qui | GS8: sex | GT8: sáb | GU8: dom | GV8: seg | GW8: ter | GX8: qua | GY8: qui | GZ8: sex | HA8: sáb | HB8: dom | HC8: seg | HD8: ter | HE8: qua | HF8: qui | HG8: sex | HH8: sáb | HI8: dom | HJ8: seg | HK8: ter | HL8: qua | HM8: qui | HN8: sex | HO8: sáb | HP8: dom | HQ8: seg | HR8: ter | HS8: qua | HT8: qui | HU8: sex | HV8: sáb | HW8: dom | HX8: seg | HY8: ter | HZ8: qua | IA8: qui | IB8: sex | IC8: sáb | ID8: dom | IE8: seg | IF8: ter | IG8: qua | IH8: qui | II8: sex | IJ8: sáb | IK8: dom | IL8: seg | IM8: ter | IN8: qua | IO8: qui | IP8: sex | IQ8: sáb | IR8: dom | IS8: seg | IT8: ter | IU8: qua | IV8: qui | IW8: sex | IX8: sáb | IY8: dom | IZ8: seg | JA8: ter | JB8: qua | JC8: qui | JD8: sex | JE8: sáb | JF8: dom | JG8: seg | JH8: ter | JI8: qua | JJ8: qui | JK8: sex | JL8: sáb | JM8: dom | JN8: seg | JO8: ter | JP8: qua | JQ8: qui | JR8: sex | JS8: sáb | JT8: dom | JU8: seg | JV8: ter | JW8: qua | JX8: qui | JY8: sex | JZ8: sáb | KA8: dom | KB8: seg | KC8: ter | KD8: qua | KE8: qui | KF8: sex | KG8: sáb | KH8: dom | KI8: seg | KJ8: ter | KK8: qua | KL8: qui | KM8: sex | KN8: sáb | KO8: dom | KP8: seg | KQ8: ter | KR8: qua | KS8: qui | KT8: sex | KU8: sáb | KV8: dom | KW8: seg | KX8: ter | KY8: qua | KZ8: qui | LA8: sex | LB8: sáb | LC8: dom | LD8: seg | LE8: ter | LF8: qua | LG8: qui | LH8: sex | LI8: sáb | LJ8: dom | LK8: seg | LL8: ter | LM8: qua | LN8: qui | LO8: sex | LP8: sáb | LQ8: dom | LR8: seg | LS8: ter | LT8: qua | LU8: qui | LV8: sex | LW8: sáb | LX8: dom | LY8: seg | LZ8: ter | MA8: qua | MB8: qui | MC8: sex | MD8: sáb | ME8: dom | MF8: seg | MG8: ter | MH8: qua | MI8: qui | MJ8: sex | MK8: sáb | ML8: dom | MM8: seg | MN8: ter | MO8: qua | MP8: qui | MQ8: sex | MR8: sáb | MS8: dom | MT8: seg | MU8: ter | MV8: qua | MW8: qui | MX8: sex | MY8: sáb | MZ8: dom | NA8: seg | NB8: ter | NC8: qua | ND8: qui | NE8: sex | NF8: sáb | NG8: dom | NH8: seg | NI8: ter | NJ8: qua
C9: Item | D9: Início | E9: Término | F9: Dias | G9: Responsável | H9: Status | I9: Observações | J9: 45658 | K9: 45659 | L9: 45660 | M9: 45661 | N9: 45662 | O9: 45663 | P9: 45664 | Q9: 45665 | R9: 45666 | S9: 45667 | T9: 45668 | U9: 45669 | V9: 45670 | W9: 45671 | X9: 45672 | Y9: 45673 | Z9: 45674 | AA9: 45675 | AB9: 45676 | AC9: 45677 | AD9: 45678 | AE9: 45679 | AF9: 45680 | AG9: 45681 | AH9: 45682 | AI9: 45683 | AJ9: 45684 | AK9: 45685 | AL9: 45686 | AM9: 45687 | AN9: 45688 | AO9: 45689 | AP9: 45690 | AQ9: 45691 | AR9: 45692 | AS9: 45693 | AT9: 45694 | AU9: 45695 | AV9: 45696 | AW9: 45697 | AX9: 45698 | AY9: 45699 | AZ9: 45700 | BA9: 45701 | BB9: 45702 | BC9: 45703 | BD9: 45704 | BE9: 45705 | BF9: 45706 | BG9: 45707 | BH9: 45708 | BI9: 45709 | BJ9: 45710 | BK9: 45711 | BL9: 45712 | BM9: 45713 | BN9: 45714 | BO9: 45715 | BP9: 45716 | BQ9: 45717 | BR9: 45718 | BS9: 45719 | BT9: 45720 | BU9: 45721 | BV9: 45722 | BW9: 45723 | BX9: 45724 | BY9: 45725 | BZ9: 45726 | CA9: 45727 | CB9: 45728 | CC9: 45729 | CD9: 45730 | CE9: 45731 | CF9: 45732 | CG9: 45733 | CH9: 45734 | CI9: 45735 | CJ9: 45736 | CK9: 45737 | CL9: 45738 | CM9: 45739 | CN9: 45740 | CO9: 45741 | CP9: 45742 | CQ9: 45743 | CR9: 45744 | CS9: 45745 | CT9: 45746 | CU9: 45747 | CV9: 45748 | CW9: 45749 | CX9: 45750 | CY9: 45751 | CZ9: 45752 | DA9: 45753 | DB9: 45754 | DC9: 45755 | DD9: 45756 | DE9: 45757 | DF9: 45758 | DG9: 45759 | DH9: 45760 | DI9: 45761 | DJ9: 45762 | DK9: 45763 | DL9: 45764 | DM9: 45765 | DN9: 45766 | DO9: 45767 | DP9: 45768 | DQ9: 45769 | DR9: 45770 | DS9: 45771 | DT9: 45772 | DU9: 45773 | DV9: 45774 | DW9: 45775 | DX9: 45776 | DY9: 45777 | DZ9: 45778 | EA9: 45779 | EB9: 45780 | EC9: 45781 | ED9: 45782 | EE9: 45783 | EF9: 45784 | EG9: 45785 | EH9: 45786 | EI9: 45787 | EJ9: 45788 | EK9: 45789 | EL9: 45790 | EM9: 45791 | EN9: 45792 | EO9: 45793 | EP9: 45794 | EQ9: 45795 | ER9: 45796 | ES9: 45797 | ET9: 45798 | EU9: 45799 | EV9: 45800 | EW9: 45801 | EX9: 45802 | EY9: 45803 | EZ9: 45804 | FA9: 45805 | FB9: 45806 | FC9: 45807 | FD9: 45808 | FE9: 45809 | FF9: 45810 | FG9: 45811 | FH9: 45812 | FI9: 45813 | FJ9: 45814 | FK9: 45815 | FL9: 45816 | FM9: 45817 | FN9: 45818 | FO9: 45819 | FP9: 45820 | FQ9: 45821 | FR9: 45822 | FS9: 45823 | FT9: 45824 | FU9: 45825 | FV9: 45826 | FW9: 45827 | FX9: 45828 | FY9: 45829 | FZ9: 45830 | GA9: 45831 | GB9: 45832 | GC9: 45833 | GD9: 45834 | GE9: 45835 | GF9: 45836 | GG9: 45837 | GH9: 45838 | GI9: 45839 | GJ9: 45840 | GK9: 45841 | GL9: 45842 | GM9: 45843 | GN9: 45844 | GO9: 45845 | GP9: 45846 | GQ9: 45847 | GR9: 45848 | GS9: 45849 | GT9: 45850 | GU9: 45851 | GV9: 45852 | GW9: 45853 | GX9: 45854 | GY9: 45855 | GZ9: 45856 | HA9: 45857 | HB9: 45858 | HC9: 45859 | HD9: 45860 | HE9: 45861 | HF9: 45862 | HG9: 45863 | HH9: 45864 | HI9: 45865 | HJ9: 45866 | HK9: 45867 | HL9: 45868 | HM9: 45869 | HN9: 45870 | HO9: 45871 | HP9: 45872 | HQ9: 45873 | HR9: 45874 | HS9: 45875 | HT9: 45876 | HU9: 45877 | HV9: 45878 | HW9: 45879 | HX9: 45880 | HY9: 45881 | HZ9: 45882 | IA9: 45883 | IB9: 45884 | IC9: 45885 | ID9: 45886 | IE9: 45887 | IF9: 45888 | IG9: 45889 | IH9: 45890 | II9: 45891 | IJ9: 45892 | IK9: 45893 | IL9: 45894 | IM9: 45895 | IN9: 45896 | IO9: 45897 | IP9: 45898 | IQ9: 45899 | IR9: 45900 | IS9: 45901 | IT9: 45902 | IU9: 45903 | IV9: 45904 | IW9: 45905 | IX9: 45906 | IY9: 45907 | IZ9: 45908 | JA9: 45909 | JB9: 45910 | JC9: 45911 | JD9: 45912 | JE9: 45913 | JF9: 45914 | JG9: 45915 | JH9: 45916 | JI9: 45917 | JJ9: 45918 | JK9: 45919 | JL9: 45920 | JM9: 45921 | JN9: 45922 | JO9: 45923 | JP9: 45924 | JQ9: 45925 | JR9: 45926 | JS9: 45927 | JT9: 45928 | JU9: 45929 | JV9: 45930 | JW9: 45931 | JX9: 45932 | JY9: 45933 | JZ9: 45934 | KA9: 45935 | KB9: 45936 | KC9: 45937 | KD9: 45938 | KE9: 45939 | KF9: 45940 | KG9: 45941 | KH9: 45942 | KI9: 45943 | KJ9: 45944 | KK9: 45945 | KL9: 45946 | KM9: 45947 | KN9: 45948 | KO9: 45949 | KP9: 45950 | KQ9: 45951 | KR9: 45952 | KS9: 45953 | KT9: 45954 | KU9: 45955 | KV9: 45956 | KW9: 45957 | KX9: 45958 | KY9: 45959 | KZ9: 45960 | LA9: 45961 | LB9: 45962 | LC9: 45963 | LD9: 45964 | LE9: 45965 | LF9: 45966 | LG9: 45967 | LH9: 45968 | LI9: 45969 | LJ9: 45970 | LK9: 45971 | LL9: 45972 | LM9: 45973 | LN9: 45974 | LO9: 45975 | LP9: 45976 | LQ9: 45977 | LR9: 45978 | LS9: 45979 | LT9: 45980 | LU9: 45981 | LV9: 45982 | LW9: 45983 | LX9: 45984 | LY9: 45985 | LZ9: 45986 | MA9: 45987 | MB9: 45988 | MC9: 45989 | MD9: 45990 | ME9: 45991 | MF9: 45992 | MG9: 45993 | MH9: 45994 | MI9: 45995 | MJ9: 45996 | MK9: 45997 | ML9: 45998 | MM9: 45999 | MN9: 46000 | MO9: 46001 | MP9: 46002 | MQ9: 46003 | MR9: 46004 | MS9: 46005 | MT9: 46006 | MU9: 46007 | MV9: 46008 | MW9: 46009 | MX9: 46010 | MY9: 46011 | MZ9: 46012 | NA9: 46013 | NB9: 46014 | NC9: 46015 | ND9: 46016 | NE9: 46017 | NF9: 46018 | NG9: 46019 | NH9: 46020 | NI9: 46021 | NJ9: 46022
D11: 45292 | E11: 45293 | F11: =(E11-D11)+1 -> 2 | H11: PENDENTE
F12: =(E12-D12)+1 -> 1 | H12: PENDENTE
F13: =(E13-D13)+1 -> 1 | H13: PENDENTE
F14: =(E14-D14)+1 -> 1 | H14: PENDENTE
F15: =(E15-D15)+1 -> 1 | H15: PENDENTE
F16: =(E16-D16)+1 -> 1 | H16: PENDENTE
F17: =(E17-D17)+1 -> 1 | H17: PENDENTE
F18: =(E18-D18)+1 -> 1 | H18: PENDENTE
F19: =(E19-D19)+1 -> 1 | H19: PENDENTE
F20: =(E20-D20)+1 -> 1 | H20: PENDENTE
F21: =(E21-D21)+1 -> 1 | H21: PENDENTE
F22: =(E22-D22)+1 -> 1 | H22: PENDENTE
F23: =(E23-D23)+1 -> 1 | H23: PENDENTE
... F40: =(E40-D40)+1 -> 1 | H40: PENDENTE
